Workbook

Sheet Doors
A1: ID | B1: Title | C1: Subtitle | D1: Location | E1: Floor | F1: Telephone | G1: Description | H1: Category | I1: Web | J1: Logo | K1: LogoName | L1: Cat_TR | M1: https://inmapper.com/zorlucenter/img/logo/
A2: carpark-301 | B2: {“id”:”carpark”} | E2: -3 | F2: - | G2: otopark, araç, otomobil, motosiklet, manevra, parking, vehicle, automobile, motorcycle, maneuver
A3: carpark-301 | B3: DRN Oto Yıkama | C3: {“id”:”floorparking”} | E3: -3 | F3: +905313051112 | G3: otomobil, yıkama, pasta, cila, temizlik, automobile, washing, cake, lacquer, cleaning | H3: servicestores | I3: www.drncarcare.com | J3: =CONCATENATE($M$1,$K3) -> https://inmapper.com/zorlucenter/img/logo/WILLIAMSCARCARE.png | K3: WILLIAMSCARCARE.png | L3: Hizmet Mağazaları
A4: entrance-301 | B4: {“id”:”entrance”} {“id”:”floormetro”} | E4: -3 | F4: - | G4: giriş, çıkış, kapı, bekleme, güvenlik, entrance, exit, door, waiting, security
A5: entrance-302 | B5: {“id”:”carpark”} {“id”:”entrance”} Zincirlikuyu | E5: -3 | F5: - | G5: giriş, çıkış, kapı, bekleme, güvenlik, entrance, exit, door, waiting, security
A6: entrance-303 | B6: {“id”:”entrance”} {“id”:”floormetro”} | E6: -3 | F6: - | G6: giriş, çıkış, kapı, bekleme, güvenlik, entrance, exit, door, waiting, security
A7: entrance-304 | B7: {“id”:”carpark”} {“id”:”entrance”} Levazım | E7: -3 | F7: - | G7: giriş, çıkış, kapı, bekleme, güvenlik, entrance, exit, door, waiting, security
A8: entrance-305 | B8: {“id”:”entrance”} {“id”:”floorparking”} | E8: -3 | F8: - | G8: giriş, çıkış, kapı, bekleme, güvenlik, entrance, exit, door, waiting, security
A9: entrance-306 | B9: {“id”:”carpark”} {“id”:”entrance”} Eataly | E9: -3 | F9: - | G9: giriş, çıkış, kapı, bekleme, güvenlik, entrance, exit, door, waiting, security
A10: ID-301 | B10: Etstur | E10: -3 | F10: +902122820808-07 | G10: tatil, deniz, bayram, otel, fırsat, holiday, sea, holidays, hotel, occasion | H10: culture_entertainment | I10: www.etstur.com | J10: =CONCATENATE($M$1,$K10) -> https://inmapper.com/zorlucenter/img/logo/ETSTUR.png | K10: ETSTUR.png | L10: Kültür & Eğlence
A11: ID-302 | B11: Levent Lostra | E11: -3 | F11: +902123536303 | G11: ayakkabı, tamir, boya, bakım, cüzdan, shoe, repair, paint, maintenance, wallet | H11: servicestores | I11: www.leventlostra.com.tr | J11: =CONCATENATE($M$1,$K11) -> https://inmapper.com/zorlucenter/img/logo/LEVENTLOSTRA.png | K11: LEVENTLOSTRA.png | L11: Hizmet Mağazaları
A12: ID-303 | B12: Dry Corner | E12: -3 | F12: +902123536337 | G12: kuru temizleme, ütü, gömlek, ceket, organik, dry cleaning, ironing, shirt, jacket, organic, dıray kornır | H12: servicestores | I12: www.drycorner.com | J12: =CONCATENATE($M$1,$K12) -> https://inmapper.com/zorlucenter/img/logo/DRYCORNER.png | K12: DRYCORNER.png | L12: Hizmet Mağazaları
A13: ID-304 | B13: Z Terzi | E13: -3 | F13: +902123536986 | G13: dikiş, onarım, tadilat, küçültme, büyültme, sewing, repair, modification, reduction, magnification | H13: servicestores | I13: www.zterzi.com | J13: =CONCATENATE($M$1,$K13) -> https://inmapper.com/zorlucenter/img/logo/ZTERZİ.png | K13: ZTERZİ.png | L13: Hizmet Mağazaları
A14: ID-306 | B14: Rossmann | E14: -3 | F14: +902123536933 | G14: kozmetik, bakım, temizlik, makyaj, aksesuar, cosmetic, care, cleaning, makeup, accessory, rosman | H14: cosmetics_health | I14: www.rossmann.com.tr | J14: =CONCATENATE($M$1,$K14) -> https://inmapper.com/zorlucenter/img/logo/ROSSMANN.png | K14: ROSSMANN.png | L14: Kozmetik & Sağlık
A15: ID-308 | B15: Vennüs Telefon Teknik | E15: -3 | F15: +902124030025 | G15: venüs, venus, telefon, tablet, teknik, teknoloji, mobil, phone, tablet, technic, technology, mobile | H15: servicestores | J15: =CONCATENATE($M$1,$K15) -> https://inmapper.com/zorlucenter/img/logo/VENNUS.png | K15: VENNUS.png | L15: Hizmet Mağazaları
A16: ID-309 | B16: Balonika | E16: -3 | F16: +902123536944 | G16: oyuncak, parti, çocuk, bebek, baskı, oyuncak, parti, çocuk, bebek, baskı | H16: culture_entertainment | J16: =CONCATENATE($M$1,$K16) -> https://inmapper.com/zorlucenter/img/logo/BALONIKA.png | K16: BALONIKA.png | L16: Kültür & Eğlence
A17: ID-310 | B17: Usta Saat | E17: -3 | F17: +902123248353 | G17: saat, pil, kayış, kordon, kadran, watch, battery, strap, cord, dial, tamir, repair | H17: servicestores | J17: =CONCATENATE($M$1,$K17) -> https://inmapper.com/zorlucenter/img/logo/USTASAAT.png | K17: USTASAAT.png | L17: Hizmet Mağazaları
A18: ID-312 | B18: Uranüs | E18: -3 | F18: +902123536912 | G18: telefon, kap, ekran koruyucu, phone, cover, screen protector, mobile oufitters | H18: electronics | J18: =CONCATENATE($M$1,$K18) -> https://inmapper.com/zorlucenter/img/logo/URANUS.png | K18: URANUS.png | L18: Elektronik
A19: ID-313 | B19: MediaMarkt | D19: ID-312 | E19: -3 | F19: +908502221500 | G19: medyamarket, elektronik, telefon, bilgisayar, laptop, teknoloji, electronics, phone, computer, laptop, technology | H19: electronics | I19: www.mediamarkt.com.tr | J19: =CONCATENATE($M$1,$K19) -> https://inmapper.com/zorlucenter/img/logo/MEDIAMARKT.png | K19: MEDIAMARKT.png | L19: Elektronik
A20: ID-314 | B20: Eve | E20: -3 | F20: - | H20: cosmetics_health | I20: www.eveshop.com.tr | J20: =CONCATENATE($M$1,$K20) -> https://inmapper.com/zorlucenter/img/logo/EVE.png | K20: EVE.png | L20: Kozmetik & Sağlık
A21: ID-315 | B21: Erkan Taş Podyum Terzi | E21: -3 | F21: +905458523899 | G21: dikiş, onarım, tadilat, küçültme, büyültme, sewing, repair, modification, reduction, magnification | H21: servicestores | J21: =CONCATENATE($M$1,$K21) -> https://inmapper.com/zorlucenter/img/logo/ERKANTAS.png | K21: ERKANTAS.png | L21: Hizmet Mağazaları
A22: ID-316 | B22: Yalçınlar | E22: -3 | F22: +902123536700 | G22: fotoğraf, makine, film, baskı, vesikalık, photography, machine, film, printing, mug shot | H22: servicestores | I22: www.fotomaks.com.tr | J22: =CONCATENATE($M$1,$K22) -> https://inmapper.com/zorlucenter/img/logo/YALÇINLAR.png | K22: YALÇINLAR.png | L22: Hizmet Mağazaları
A23: ID-317 | B23: Zorlu PSM | C23: {“id”:”floormetro”} | E23: -3 | F23: +908502226776 | G23: etkinlik, gösteri, tiyatro, konser, bilet, activity, show, theater, concert, ticket | H23: culture_entertainment | L23: Kültür & Eğlence
A24: ID-318 | B24: Penelope | E24: -3 | F24: +902123536963 | G24: yatak, uyku, yastık, kılıf, tekstil, bed, sleeping, pillow, sheath, textile, penelop | H24: home_decoration | I24: www.penelopebedroom.com | J24: =CONCATENATE($M$1,$K24) -> https://inmapper.com/zorlucenter/img/logo/PENELOPE.png | K24: PENELOPE.png | L24: Ev & Dekorasyon
A25: locker-301 | B25: {“id”:”locker”} | E25: -3 | F25: - | G25: emanet dolabı, safety deposit locker, box | H25: services | L25: Hizmet Mağazaları
A26: metrobus-301 | B26: {“id”:”metro”} {“id”:”metrobus”} | E26: -3 | F26: - | G26: metro, metrobüs, iett, otobüs, durak, subway, metrobus, iett, bus, stall
A27: baby-201 | B27: {“id”:”baby”} | E27: -2 | F27: - | G27: bebek, oda, bakım, emzik, meme, baby, room, care, pacifier, breast
A28: baby-202 | B28: {“id”:”baby”} | E28: -2 | F28: - | G28: bebek, oda, bakım, emzik, meme, baby, room, care, pacifier, breast
A29: ID-201 | B29: Zor {“id”:”exchange”} | E29: -2 | F29: +902123536268 | G29: döviz, para, dolar, euro, altın, currency, currency, dollar, euro, gold | H29: servicestores | J29: =CONCATENATE($M$1,$K29) -> https://inmapper.com/zorlucenter/img/logo/ZORDÖVİZ.png | K29: ZORDÖVİZ.png | L29: Hizmet Mağazaları
A30: ID-201A | B30: Paribu Cineverse | E30: -2 | F30: +908502200967 | G30: sinema, bilet, film, mısır, koltuk, cinema, ticket, movie, popcorn, seat | H30: culture_entertainment | I30: www.paribucineverse.com | J30: =CONCATENATE($M$1,$K30) -> https://inmapper.com/zorlucenter/img/logo/PARIBUCINEVERSE.png | K30: PARIBUCINEVERSE.png | L30: Kültür & Eğlence
A31: ID-201B | B31: House of Design | E31: -2 | F31: +905427330715 | G31: tasarım, akesuar, design, accessories | H31: accessories_jewellery | I31: www.houseofdesign.store.com | J31: =CONCATENATE($M$1,$K31) -> https://inmapper.com/zorlucenter/img/logo/HOUSEOFDESIGN.png | K31: HOUSEOFDESIGN.png | L31: Aksesuar & Mücevher
A32: ID-202 | B32: Dagi | E32: -2 | F32: +908502597504 | G32: iç çamaşırı, pijama, mayo, çorap, uyku, lingerie, pajamas, swimsuit, stockings, sleeping | H32: fashion | I32: www.dagi.com.tr | J32: =CONCATENATE($M$1,$K32) -> https://inmapper.com/zorlucenter/img/logo/DAGİ.png | K32: DAGİ.png | L32: Giyim
A33: ID-203 | B33: Tartine et Chocolat | E33: -2 | F33: +902123536050 | G33: çocuk, bebek, elbise, oyuncak, yatak, child, baby, dress, toy, bed, tartin et çaklıt | H33: kids | I33: www.tartine-et-chocolat.fr | J33: =CONCATENATE($M$1,$K33) -> https://inmapper.com/zorlucenter/img/logo/TARTINEETCHOCOLAT.png | K33: TARTINEETCHOCOLAT.png | L33: Çocuk
A34: ID-204 | B34: Skechers | E34: -2 | F34: +902123536543 | G34: ayakkabı, spor, sandalet, shoes, sports, sandals | H34: shoes_bags | I34: www.skechers.com | J34: =CONCATENATE($M$1,$K34) -> https://inmapper.com/zorlucenter/img/logo/SKECHERS.png | K34: SKECHERS.png | L34: Ayakkabı & Çanta
A35: ID-205 | B35: Starbucks | E35: -2 | F35: +902123536110 | G35: kahve, içecek, yiyecek, kek, sandviç, coffee, beverage, food, cake, sandwich, sıtarbaks | H35: restaurant_cafe | I35: www.starbucks.com.tr | J35: =CONCATENATE($M$1,$K35) -> https://inmapper.com/zorlucenter/img/logo/STARBUCKS.png | K35: STARBUCKS.png | L35: Restoran & Cafe
A36: ID-206 | B36: House of SuperStep | E36: -2 | F36: - | H36: shoes_bags | I36: www.houseofsuperstep.com | J36: =CONCATENATE($M$1,$K36) -> https://inmapper.com/zorlucenter/img/logo/HOUSEOFSUPERSTEP.png | K36: HOUSEOFSUPERSTEP.png | L36: Ayakkabı & Çanta
A37: ID-207 | B37: Sephora | E37: -2 | F37: +902127032087 | G37: makyaj, krem, bakım, ruj, pudra, makeup, cream, care, lipstick | H37: cosmetics_health | I37: www.sephora.com | J37: =CONCATENATE($M$1,$K37) -> https://inmapper.com/zorlucenter/img/logo/SEPHORA.png | K37: SEPHORA.png | L37: Kozmetik & Sağlık
A38: ID-208 | B38: Under Armour | E38: -2 | F38: +902123536544 | G38: spor, giyim, ayakkabı, tshirt, eşofman, sport, clothing, shoes, tshirt, tracksuit, andır armor | H38: fashion | I38: www.underarmour.com | J38: =CONCATENATE($M$1,$K38) -> https://inmapper.com/zorlucenter/img/logo/UNDERARMOUR.png | K38: UNDERARMOUR.png | L38: Giyim
A39: ID-209 | B39: Adidas | E39: -2 | F39: +902123536230 | G39: spor, giyim, ayakkabı, tshirt, eşofman, sport, clothing, shoes, tshirt, tracksuit | H39: fashion | I39: www.adidas.com | J39: =CONCATENATE($M$1,$K39) -> https://inmapper.com/zorlucenter/img/logo/ADİDAS.png | K39: ADİDAS.png | L39: Giyim
A40: ID-210 | B40: Asics | E40: -2 | F40: +902123536292 | G40: spor, giyim, ayakkabı, tshirt, eşofman, sport, clothing, shoes, tshirt, tracksuit | H40: fashion | I40: www.asicstr.com | J40: =CONCATENATE($M$1,$K40) -> https://inmapper.com/zorlucenter/img/logo/ASICS.png | K40: ASICS.png | L40: Giyim
...

Sheet Extension
A1: Time | B1: Stage | C1: ID | D1: title_tr | E1: subtext_tr | F1: footnote_tr | G1: title_en | H1: subtext_en | I1: footnote_en | J1: icon | K1: img | L1: enabled | M1: start_date | N1: end_date | O1: status
A2: 17.11.2022 09:00:00 | B2: PROD | C2: ID116 | D2: Memorial Wellness'de X-Scan ile Ücretsiz Vücut Analizi! | E2: Uygulamayı indirerek QR okutmak için aşağıdaki butonu tıklayınız! | F2: Kampanya dahilinde Memorial Wellness Zorlu'da X-Scan ile Ücretsiz Vücut Analizi yapılacaktır. 31 Ağustos 2023 tarihine kadar geçerlidir. Zorlu World üyelerinin kampanyadan yararlanması için Zorlu World uygulamasından Memorial Wellness mağazasındaki QR kodu okutması gerekmektedir. Zorlu World ve Memorial Wellness kampanyada değişiklik yapma hakkını saklı tutar. Zorlu World, Zorlu Yapı Yatırım A.Ş. Müşteri Ödül Programı’dır. | G2: Free Body Analysis with X-Scan at Memorial Wellness! | H2: The app can be downloaded via button below in order to scan the QR code! | I2: In the scope of the campaign, body analysis with X-Scan can be benefit as free of charge at Memorial Wellness Zorlu until 31 May 2023. Zorlu World members are required to open the QR reading from the Zorlu World application and scan the QR code next to the cash register at Memorial Wellness in order to benefit from the campaign. Zorlu World and Memorial Wellness reserve the right to change the campaign. Zorlu World, Zorlu Yapı Yatırım A.Ş. Customer Reward Program. | J2: img/zw/icon/offer.png | K2: Memorial-Wellnessb-750x600.jpg | L2: TRUE | M2: 17.11.2022 | N2: 31.08.2023 | O2: active
A3: 05.12.2022 09:00:00 | B3: PROD | C3: ID061R | D3: Long Bar'da %10 İndirim! | E3: Uygulamayı indirerek kod almak için aşağıdaki butonu tıklayınız! | F3: Benzersiz lezzetler ve imza kokteyller ile dünyanın en iyilerini seyretmek için sen de Long Bar’da yerini al, futbol heyecanını Zorlu World’e özel %10 indirimli yaşa! Kampanya, Long Bar’dan vereceğiniz 200 TL ve üzeri siparişlerinizde 18 Aralık 2022 tarihine kadar geçerlidir. Diğer kampanyalarla birleştirilemez. Zorlu World üyelerinin kampanyadan yararlanması için Zorlu World uygulamasından kod alması ve alınmış olan kodu Long Bar kasasında bildirmesi gerekmektedir. Zorlu World ve Raffles Istanbul kampanyada değişiklik yapma hakkını saklı tutar. Zorlu World, Zorlu Yapı Yatırım A.Ş. Müşteri Ödül Programı’dır. 18 Aralık 2022 tarihine kadar geçerlidir. | G3: 10% Off at Long Bar! | H3: The app can be downloaded via button below in order to get the campaign code! | I3: Show up for your team, and watch all the games with delicious drafts, snacks, and signature cocktails to pitch your excitement with a 10% discount privilege for Zorlu World! The campaign is valid for the orders that is 200 TL or more, to be made at Long Bar until 18 December 2022. Cannot be combined with other campaigns. Zorlu World members are required to obtain a code from the Zorlu World application and notify the representative at the Long Bar cash register in order to benefit from the campaign. Zorlu World and Long Bar reserve the right to make changes to the campaign. Zorlu World, Zorlu Yapı Yatırım A.Ş. It is the Customer Reward Program. Valid until 18 December 2022 | J3: img/zw/icon/offer.png | K3: Long-Bar-750x600.jpg | L3: TRUE | M3: 05.12.2022 | N3: 18.12.2022 | O3: passive
A4: 05.12.2022 09:00:00 | B4: PROD | C4: ID013 | D4: Tommi Brasserie'de Kahvaltı veya Öğle Yemeği Alımına %20 İndirim! | E4: Uygulamayı indirerek kod almak için aşağıdaki butonu tıklayınız! | F4: Kampanya kapsamında, Tommi Brasserie’den her gün saat 15:00 öncesinde vereceğiniz kahvaltı veya öğle yemeği siparişinize %20 indirim uygulanacaktır. 31 Aralık 2022 tarihine kadar geçerlidir. Diğer kampanyalarla birleştirilemez. Zorlu World üyelerinin kampanyadan yararlanması için Zorlu World uygulamasından kod alması ve alınmış olan kodu Tommi Brasserie kasasında restoran yetkilisine bildirmesi gerekmektedir. Zorlu World ve Tommi Brasserie kampanyada değişiklik yapma hakkını saklı tutar. Zorlu World, Zorlu Yapı Yatırım A.Ş. Müşteri Ödül Programı’dır. 31 Aralık 2022 tarihine kadar geçerlidir. | G4: %20 Off for Breakfeast or Lunch at Tommi Brasserie! | H4: The app can be downloaded via button below in order to get the campaign code! | I4: The campaign is valid until 3:00 pm every day for breakfeast or lunch orders to be made at Tommi Braserrie Zorlu until 31 December 2022. %20 discount will be applied within the scope of the campaign. Cannot be combined with other campaigns. Zorlu World members are required to obtain a code from the Zorlu World application and notify the restaurant representative at the Tommi Brasserie cash register in order to benefit from the campaign. Zorlu World and Tommi Brasserie reserve the right to make changes to the campaign. Zorlu World, Zorlu Yapı Yatırım A.Ş. It is the Customer Reward Program. Valid until 31 December 2022 | J4: img/zw/icon/offer.png | K4: Tommi-750x600.jpg | L4: TRUE | M4: 05.12.2022 | N4: 31.12.2022 | O4: passive
A5: 14.09.2022 09:00:00 | B5: PROD | C5: ID-235 | D5: Jacadi Paris Zorlu'da Tüm İndirimlere Ek %10 İndirim! | E5: Uygulamayı indirerek kod almak için aşağıdaki butonu tıklayınız! | F5: Kampanya, Jacadi Paris Zorlu mağazasında 31 Aralık 2023 tarihine kadar yapılacak tüm ürün alışverişlerinde geçerlidir. Tüm indirimlere ek %10 indirim uygulanacaktır. Zorlu World üyelerinin kampanyadan yararlanması için Zorlu World uygulamasından kod alması ve alınmış olan kodu Jacadi Paris kasasında mağaza yetkilisine bildirmesi gerekmektedir. Zorlu World ve Jacadi Paris kampanyada değişiklik yapma hakkını saklı tutar. Zorlu World, Zorlu Yapı Yatırım A.Ş. Müşteri Ödül Programı’dır. 31 Aralık 2023 tarihine kadar geçerlidir. | G5: Additional 10% Discount Privilege at Jacadi Paris! | H5: The app can be downloaded via button below in order to get the campaign code! | I5: The campaign is valid forall merchandise purchases made at Zorlu Center Jacadi Paris store until 31 December 2023. Additional 10% discount will be applied after all other valid discounts. Zorlu World members are required to obtain a code from the Zorlu World application and notify the store representative at the Jacadi Paris cash register in order to benefit from the campaign. Zorlu World and Jacadi Paris reserve the right to make changes to the campaign. Zorlu World, Zorlu Yapı Yatırım A.Ş. It is the Customer Reward Program. Valid until 31 December 2023 | J5: img/zw/icon/offer.png | K5: Jakardi-750x600.jpg | L5: TRUE | M5: 02.01.2023 | N5: 31.12.2023 | O5: active
A6: 14.04.2023 09:00:00 | B6: PROD | C6: ID113 | D6: Penelope Bedroom'da Seçili Ürünlerde %25 İndirim! | E6: Uygulamayı indirerek kod almak için aşağıdaki butonu tıklayınız! | F6: Kampanya, Zorlu Center Penelope Bedroom mağazasında 30 Nisan 2023 tarihine kadar yapılacak Bamboo Yorgan ve Bamboo Yastık model alışverişlerinde geçerlidir. %25 indirim uygulanacaktır. Zorlu World üyelerinin kampanyadan yararlanması için Zorlu World uygulamasından kod alması ve alınmış olan kodu Penelope Bedroom mağaza kasasında mağaza yetkilisine bildirmesi gerekmektedir. Zorlu World ve Penelope Bedroom kampanyada değişiklik yapma hakkını saklı tutar. Zorlu World, Zorlu Yapı Yatırım A.Ş. Müşteri Ödül Programı’dır. 30 Nisan 2023 tarihine kadar geçerlidir. | G6: 25% Off at Penelope Bedroom! | H6: The app can be downloaded via button below in order to get the campaign code! | I6: The campaign is valid for Bamboo pillow and Bamboo blanket purchases made at Zorlu Center Penelope Bedroom store until 30 April 2023. 25% discount will be applied. Zorlu World members are required to obtain a code from the Zorlu World application and notify the store representative at the Penelope Bedroom cash register in order to benefit from the campaign. Zorlu World and Penelope Bedroom reserve the right to make changes to the campaign. Zorlu World, Zorlu Yapı Yatırım A.Ş. It is the Customer Reward Program. Valid until 30 April 2023 | J6: img/zw/icon/offer.png | K6: Penelope-750x600-4.jpg | L6: TRUE | M6: 14.04.2023 | N6: 30.04.2023 | O6: passive
A7: 14.09.2022 09:00:00 | B7: PROD | C7: ID108 | D7: English Home’da 400 TL ve üzeri Alışverişlerinizde 50 TL indirim! | E7: Uygulamayı indirerek kod almak için aşağıdaki butonu tıklayınız! | F7: Kampanya, sadece English Home Zorlu mağazasında 31 Aralık 2023 tarihine kadar yapılacak 400 TL ve üzeri alışverişlerde geçerlidir. Tüm kampanya ve indirimlere ek 50 TL indirim uygulanacaktır. Matrah katlarında geçerli değildir. Zorlu World üyelerinin kampanyadan yararlanması için Zorlu World uygulamasından kod alması ve alınmış olan kodu English Home mağaza kasasında mağaza yetkilisine bildirmesi gerekmektedir. Zorlu World ve English Home kampanyada değişiklik yapma hakkını saklı tutar. Zorlu World, Zorlu Yapı Yatırım A.Ş. Müşteri Ödül Programı’dır. 31 Aralık 2023 tarihine kadar geçerlidir. | G7: 50 TL Off for 400 TL and more purchases at English Home! | H7: The app can be downloaded via button below in order to get the campaign code! | I7: The campaign is valid for 400 TL and more purchases to be made at only English Home Zorlu store until 31 December 2023. 50 TL discount will be applied to these purchases and can be discounted after all other campaigns and discounts. The campaign is not valid for the exponential tax base applications. Zorlu World members are required to obtain a code from the Zorlu World application and notify the store representative at the English Home cash register in order to benefit from the campaign. Zorlu World and English Home reserve the right to make changes to the campaign. Zorlu World, Zorlu Yapı Yatırım A.Ş. It is the Customer Reward Program. Valid until 31 December 2023 | J7: img/zw/icon/offer.png | K7: English-Home-750X600.jpg | L7: TRUE | M7: 04.01.2023 | N7: 31.12.2023 | O7: active
A8: 14.09.2022 09:00:00 | B8: PROD | C8: ID-154 | D8: BAQA'da 10.000 TL ve Üzeri Alışverişinize %10 İndirim! | E8: Uygulamayı indirerek kod almak için aşağıdaki butonu tıklayınız! | F8: Kampanya dahilinde 31 Aralık 2023 tarihine kadar, sadece BAQA Zorlu mağazasından yapacağınız 10.000 TL ve üzeri alışverişlerinize %10 indirim uygulanacaktır. Mağazada geçerli başka indirim ve kampanyalara ek olarak kullanılabilir. Zorlu World üyelerinin kampanyadan yararlanması için Zorlu World uygulamasından kod alması ve alınmış olan kodu BAQA mağaza kasasında mağaza yetkilisine bildirmesi gerekmektedir. Zorlu World ve BAQA kampanyada değişiklik yapma hakkını saklı tutar. Zorlu World, Zorlu Yapı Yatırım A.Ş. Müşteri Ödül Programı’dır. 31 Aralık 2023 tarihine kadar geçerlidir. | G8: %10 Off at BAQA Zorlu! | H8: The app can be downloaded via button below in order to get the campaign code! | I8: Within the scope of the campaign, until 31 December 2023, 10% discount can be received in addition to all discounts for the 10.000 TL and more purchases to be made at BAQA Zorlu store only. The campaign is valid for all product purchases. A code must be obtained from the Zorlu World mobile application to benefit from the campaign. Zorlu World members are required to obtain a code from the Zorlu World application and notify the store representative at the BAQA cash register in order to benefit from the campaign. Zorlu World and BAQA reserve the right to make changes to the campaign. Zorlu World, Zorlu Yapı Yatırım A.Ş. the Customer Reward Program. Valid until 31 December 2023 | J8: img/zw/icon/offer.png | K8: BAQA-750X600.jpg | L8: TRUE | M8: 03.01.2023 | N8: 31.12.2023 | O8: active
A9: 14.09.2022 09:00:00 | B9: PROD | C9: ID024 | D9: MAC Zorlu'da Hediye Ders Ayrıcalığı | E9: Uygulamayı indirerek kod almak için aşağıdaki butonu tıklayınız! | F9: Kampanya, MAC Zorlu'da 31 Aralık 2023 tarihine kadar geçerlidir. Kampanya kampsamında yapılacak %10 indirimli ve blokajlı yıllık üyelik kayıtlarında geçerli; aletli pilates, boks veya yüzme alanlarının birinden özel ders hediye edilecektir. Diğer kampanyalarla birleştirilemez. Zorlu World üyelerinin kampanyadan yararlanması için Zorlu World uygulamasından kod alması ve alınmış olan kodu MAC Zorlu yetkilisine bildirmesi gerekmektedir. Detaylı bilgi için ; 0212 970 16 53 Zorlu World ve MAC Zorlu mağazası kampanyada değişiklik yapma hakkını saklı tutar. Zorlu World, Zorlu Yapı Yatırım A.Ş. Müşteri Ödül Programı’dır. 31 Aralık 2023'e kadar geçerlidir. | G9: Private Lesson Privilege at MAC Zorlu | H9: The app can be downloaded via button below in order to get the campaign code! | I9: The campaign will be valid at MAC Zorlu until 31 December 2023 for %10 discounted 1 year membership registration(Blockage will be applied.). Private lesson on pilates with eqipment, boxing and swimming are the options for the campaign and one of them need to be choosen. The campaign cannot be combined with other campaigns. Do not forget to obtain your code from Zorlu World! For the details get contact with; 0212 970 16 53. In order to benefit from the campaign, Zorlu World members are required to obtain a code from the Zorlu World application and notify the store representative at the MAC Zorlu store cash register. Zorlu World and MAC Zorlu store reserve the right to change the campaign. Zorlu World, Zorlu Yapı Yatırım A.Ş. Customer Reward Program. Valid until 31 December 2023 | J9: img/zw/icon/offer.png | K9: Mac-750X600.jpg | L9: TRUE | M9: 02.01.2023 | N9: 31.12.2023 | O9: active
A10: 14.09.2022 09:00:00 | B10: PROD | C10: ID-146 | D10: Vario Zorlu'da %10 İndirim | E10: Uygulamayı indirerek kod almak için aşağıdaki butonu tıklayınız! | F10: Kampanya dahilinde 31 Aralık 2023 tarihine kadar sadece Vario Zorlu mağazasında, tüm indirimlere ek olarak %10 indirim uygulanacaktır. Kampanya tüm ürün alışverişlerinde geçerlidir. Kampanyadan faydalanmak için Zorlu World mobil uygulamasından kod alınması gerekmektedir. Zorlu World üyelerinin kampanyadan yararlanması için Zorlu World uygulamasından kod alması ve alınmış olan kodu Vario kasasında mağaza yetkilisine bildirmesi gerekmektedir. Zorlu World ve Vario kampanyada değişiklik yapma hakkını saklı tutar. Zorlu World, Zorlu Yapı Yatırım A.Ş. Müşteri Ödül Programı’dır. 31 Aralık 2023 tarihine kadar geçerlidir. | G10: 10% Off at Vario Zorlu! | H10: The app can be downloaded via button below in order to get the campaign code! | I10: Within the scope of the campaign, until 31 December 2023, only Vario Zorlu store will receive 10% discount in addition to all discounts. The campaign is valid for all product purchases. A code must be obtained from the Zorlu World mobile application to benefit from the campaign. Zorlu World members are required to obtain a code from the Zorlu World application and notify the store representative at the Vario cash register in order to benefit from the campaign. Zorlu World and Vario reserve the right to make changes to the campaign. Zorlu World, Zorlu Yapı Yatırım A.Ş. the Customer Reward Program. Valid until 31 December 2023 | J10: img/zw/icon/offer.png | K10: Vario-750x600.jpg | L10: TRUE | M10: 02.01.2023 | N10: 31.12.2023 | O10: active
A11: 14.09.2022 09:00:00 | B11: PROD | C11: ID035 | D11: Valeron'da 4.000 TL ve Üzeri Alışverişinize 750 TL İndirim! | E11: Uygulamayı indirerek kod almak için aşağıdaki butonu tıklayınız! | F11: Kampanya dahilinde 31 Aralık 2023 tarihine kadar Valeron Zorlu'dan yapılacak 4.000 TL ve üzeri alışverişlerde 750 TL indirim uygulanacaktır. Zorlu World üyelerinin kampanyadan yararlanması için Zorlu World uygulamasından kod alması ve alınmış olan kodu Valeron kasasında mağaza yetkilisine bildirmesi gerekmektedir. Zorlu World ve Valeron kampanyada değişiklik yapma hakkını saklı tutar. Zorlu World, Zorlu Yapı Yatırım A.Ş. Müşteri Ödül Programı’dır. 31 Aralık 2023 tarihine kadar geçerlidir. | G11: 750 TL Discount at Valeron Zorlu! | H11: The app can be downloaded via button below in order to get the campaign code! | I11: "Within the scope of the campaign, 750TL discount will be applied for purchases of 4.000 TL and above from Linens Zorlu until 31 December 2023. In order to benefit from the campaign, Zorlu World members are required to obtain a code from the Zorlu World application and notify the store representative at the Valeron cash register. Zorlu World and Valeron reserve the right to make changes to the campaign. Zorlu World, Zorlu Yapı Yatırım A.Ş. It is the Customer Reward Program. Valid until 31 December 2023" | J11: img/zw/icon/offer.png | K11: VALERON-750x600.jpg | L11: TRUE | M11: 03.01.2023 | N11: 31.12.2023 | O11: active
A12: 14.09.2022 09:00:00 | B12: PROD | C12: ID101 | D12: Linens'de 1.500 TL ve Üzeri Alışverişinize 250 TL İndirim! | E12: Uygulamayı indirerek kod almak için aşağıdaki butonu tıklayınız! | F12: Kampanya dahilinde 31 Aralık 2023 tarihine kadar Linens Zorlu'dan yapılacak 1.500 TL ve üzeri alışverişlere 250TL indirim uygulanacaktır. Perde kategorisindeki ürünler kampanyaya dahil değildir. Zorlu World üyelerinin kampanyadan yararlanması için Zorlu World uygulamasından kod alması ve alınmış olan kodu Linens mağaza kasasında mağaza yetkilisine bildirmesi gerekmektedir. Zorlu World ve Linens kampanyada değişiklik yapma hakkını saklı tutar. Zorlu World, Zorlu Yapı Yatırım A.Ş. Müşteri Ödül Programı’dır. 31 Aralık 2023 tarihine kadar geçerlidir. | G12: 250 TL Discount at Linens Zorlu! | H12: The app can be downloaded via button below in order to get the campaign code! | I12: Within the scope of the campaign, 250TL discount will be applied for purchases of 1.500 TL and above from Linens Zorlu until 31 December 2023. Products in the curtain category are not included in the campaign. In order to benefit from the campaign, Zorlu World members are required to obtain a code from the Zorlu World application and notify the store representative at the Linens cash register. Zorlu World and Linens reserve the right to make changes to the campaign. Zorlu World, Zorlu Yapı Yatırım A.Ş. It is the Customer Reward Program. Valid until 31 December 2023 | J12: img/zw/icon/offer.png | K12: LINENS-750x600.jpg | L12: TRUE | M12: 03.01.2023 | N12: 31.12.2023 | O12: active
A13: 14.09.2022 09:00:00 | B13: PROD | C13: ID-236 | D13: Columbia Zorlu'da Tüm İndirimlere Ek %5 İndirim! | E13: Uygulamayı indirerek kod almak için aşağıdaki butonu tıklayınız! | F13: Kampanya dahilinde; Columbia Zorlu mağazasından yapılacak 10.000 TL ve üzeri tüm alışverişlerde, tüm indirimlere ek olarak %5 indirim uygulanacaktır. 31 Aralık 2023 tarihine kadar geçerlidir. Zorlu World üyelerinin kampanyadan yararlanması için Zorlu World uygulamasından kod alması ve alınmış olan kodu Columbia mağaza kasasında mağaza yetkilisine bildirmesi gerekmektedir. Zorlu World ve Columbia kampanyada değişiklik yapma hakkını saklı tutar. Zorlu World, Zorlu Yapı Yatırım A.Ş. Müşteri Ödül Programı’dır. 31 Aralık 2023 tarihine kadar geçerlidir. | G13: Additional 5% Discount at Columbia Zorlu! | H13: The app can be downloaded via button below in order to get the campaign code! | I13: Within the scope of the campaign, an additional 5% discount on all other discounts, will be applied to your shopping that has a price of 10.000 TL and more. In order to benefit from the campaign, Zorlu World members are required to obtain a code from the Zorlu World application and notify the store representative at the Columbia Zorlu cash register. Zorlu World and Columbia reserve the right to change the campaign. Zorlu World, Zorlu Yapı Yatırım A.Ş. Customer Reward Program. Valid until 31 December 2023 | J13: img/zw/icon/offer.png | K13: Columbia-V3-750x600.jpg | L13: TRUE | M13: 02.01.2023 | N13: 31.12.2023 | O13: active
... A42: 22.12.2022 09:00:00 | B42: PROD | C42: ID119B | D42: Collection Point’de 2.000 TL ve üzeri Alışverişlerinde %5 indirim! | E42: Uygulamayı indirerek kod almak için aşağıdaki butonu tıklayınız! | F42: Kampanya, Collection Point Zorlu mağazasında 31 Aralık 2023 tarihine kadar yapılacak 2.000 TL ve üzeri alışverişlerde geçerlidir.%5 indirim uygulanacaktır. Mücevher ürünleri kampanyaya dahil değildir. Zorlu World üyelerinin kampanyadan yararlanması için Zorlu World uygulamasından QR okumayı açması ve Collection Point mağazasında kasa yanındaki QR kodu okutması gerekmektedir. Zorlu World ve Collection Point kampanyada değişiklik yapma hakkını saklı tutar. Zorlu World, Zorlu Yapı Yatırım A.Ş. Müşteri Ödül Programı’dır. 31 Aralık 2023 tarihine kadar geçerlidir. | G42: 5% Off for 2.000 TL and more purchases at Collection Point! | H42: The app can be downloaded via button below in order to get the campaign code! | I42: The campaign is valid for 2.000 TL and more purchases to be made at Collection Point Zorlu store until 31 December 2023. 5% discount will be applied to the merchandises. Moser and George Jensen merchandises are not included to the campaign. Zorlu World members are required to open the QR reading from the Zorlu World application and scan the QR code next to the cash register at Collection Point store in order to benefit from the campaign. Zorlu World and Collection Point reserve the right to make changes to the campaign. Zorlu World, Zorlu Yapı Yatırım A.Ş. It is the Customer Reward Program. Valid until 31 December 2023 | J42: img/zw/icon/offer.png | K42: Collection-Point-750X600-a.jpg | L42: TRUE | M42: 10.05.2023 | N42: 31.12.2023 | O42: active

Sheet Changes
A1: ID | B1: Title | C1: Subtitle | D1: Location | E1: Floor | F1: Telephone | G1: Description | H1: Category | I1: Web | J1: Logo | K1: LogoName | L1: Cat_TR | M1: DATE | N1: STATUS | O1: UNTIL
A2: ID-246 | B2: Primestore | E2: -2 | F2: +902129123776 | G2: ayakkabı, çanta, bot, aksesuar, sandalet, shoes, bags, boots, accessories, sandals | H2: Ayakkabı & Çanta | I2: www.primestore.com.tr | J2: =CONCATENATE(Doors!$M$1,$K2) -> https://inmapper.com/zorlucenter/img/logo/PRIMESTORE.png | K2: PRIMESTORE.png | N2: CLOSED
A3: ID-250 | B3: Luzdemia | E3: -2 | F3: +902125148260 | G3: aksesuar, küpe, kolye, bileklik, yüzük, accessory, earring, necklace, wristband, ring | H3: Aksesuar & Mücevher | I3: www.luzdemia.com | J3: =CONCATENATE(Doors!$M$1,$K3) -> https://inmapper.com/zorlucenter/img/logo/LUZDEMIA.png | K3: LUZDEMIA.png | N3: CLOSED
A4: ID-127 | B4: Pizza Hut | E4: -1 | F4: +908502149034 | G4: yemek, lazanya, fast food, sarımsaklı ekmek, food, lasagna, fast food, garlic bread, pizza hat | H4: fastfood | I4: www.pizzahut.com.tr | J4: =CONCATENATE(Doors!$M$1,$K4) -> https://inmapper.com/zorlucenter/img/logo/PIZZAHUT.png | K4: PIZZAHUT.png | L4: Fast Food | N4: CLOSED
A5: valet-301 | B5: Bob {“id”:”valet”} ({“id”:”floorparking”}) | E5: -3 | F5: +908502590262 | G5: vale, park, araba, bilet, rezervasyon, valet, parking, car, ticket, booking | H5: services | L5: Hizmetler | N5: CLOSED
A6: ID070 | B6: Electrip Park Alanı | E6: 0 | F6: - | G6: araç, elektrik, şarj, vehicle, electric, charger | H6: services | L6: Hizmetler | N6: CLOSED
A7: ID061R | B7: Huqqa | E7: 0 | F7: - | G7: pizza, hamburger, et, salata, nargile, pizza, hamburger, meat, salad, hookah, hukka | H7: restaurant_cafe | L7: Restoran & Cafe | N7: CLOSED
A8: ID-124 | B8: MMY Tantuni | E8: -1 | F8: +902123431555 | G8: yemek, fast food, tantuni | H8: fastfood | I8: www.mmytantuni.com | J8: =CONCATENATE(Doors!$M$1,$K8) -> https://inmapper.com/zorlucenter/img/logo/MMYTANTUNİ.png | K8: MMYTANTUNİ.png | L8: Fast Food | N8: CLOSED
A9: ID055 | B9: La Vina | E9: 0 | F9: +902123536655 | G9: ispanyol, paella, tapas, gazpacho, içki, spanish, paella, tapas, gazpacho, drink | H9: restaurant_cafe | I9: www.lavinarestaurant.com | J9: =CONCATENATE(Doors!$M$1,$K9) -> https://inmapper.com/zorlucenter/img/logo/LAVINA.png | K9: LAVINA.png | L9: Restoran & Cafe | N9: CLOSED
A10: ID-126 | B10: Cold Stone | E10: -1 | F10: +905313687836 | G10: koldsıton, creamery, dondurma, ice cream | H10: restaurant_cafe | I10: www.coldstonecreamery.com.tr | J10: =CONCATENATE(Doors!$M$1,$K10) -> https://inmapper.com/zorlucenter/img/logo/COLDSTONE.png | K10: COLDSTONE.png | L10: Restoran & Cafe | N10: CLOSED
A11: ID119F | B11: MUSE FOR ALL | E11: 1 | F11: +902122250777 | H11: fashion | I11: www.museforall.com/tr | J11: =CONCATENATE(Doors!$M$1,$K11) -> https://inmapper.com/zorlucenter/img/logo/MUSEFORALL.png | K11: MUSEFORALL.png | L11: Giyim | M11: 01.02.2023 | N11: CLOSED
A12: ID001B | B12: Vakko Couture | E12: 0 | F12: +902127085036 | G12: erkek, kadın, giyim, moda, ayakkabı, man, woman, clothing, fashion, shoes, sen loren | H12: fashion | I12: www.vakko.com | J12: =CONCATENATE(Doors!$M$1,$K12) -> https://inmapper.com/zorlucenter/img/logo/VAKKOCOUTURE.png | K12: VAKKOCOUTURE.png | L12: Giyim | M12: 15.02.2023 | N12: CLOSED
A13: ID001B | B13: Fabiana Filippi | E13: 0 | F13: - | G13: erkek, kadın, giyim, moda, ayakkabı, man, woman, clothing, fashion, shoes, sen loren | H13: fashion | I13: www.fabianafilippi.com | J13: =CONCATENATE(Doors!$M$1,$K13) -> https://inmapper.com/zorlucenter/img/logo/FABIANAFILIPPI.png | K13: FABIANAFILIPPI.png | L13: Giyim | M13: 15.02.2023 | N13: OPENED
A14: ID119F | B14: Boho Loves Elif Mısırlı | E14: 1 | H14: fashion | I14: www.boholoves.com | J14: =CONCATENATE(Doors!$M$1,$K14) -> https://inmapper.com/zorlucenter/img/logo/BOHOLOVESELIFMISIRLI.png | K14: BOHOLOVESELIFMISIRLI.png | L14: Giyim | M14: 01.03.2023 | N14: OPENED
A15: ID075 | B15: Walkers Market | E15: 0 | F15: - | G15: alkol, içki, kokteyl, alcohol, drink, cocktail, viski, whisky | H15: restaurant_cafe | L15: Restoran & Cafe | N15: CLOSED
A16: ID126 | B16: Mariposa | E16: 1 | F16: +908505324386 | G16: çocuk, uyku, bebek, elbise, oyuncak, child, sleeping, baby, dress, toy | H16: restaurant_cafe | I16: www.funloft.com.tr | J16: =CONCATENATE(Doors!$M$1,$K16) -> https://inmapper.com/zorlucenter/img/logo/MARIPOSABURGER.png | K16: MARIPOSABURGER.png | L16: Restoran & Cafe | M16: 09.03.2023 | N16: CLOSED
A17: ID-315 | B17: Erkan Taş Podyum Terzi | E17: -3 | F17: +905458523899 | G17: dikiş, onarım, tadilat, küçültme, büyültme, sewing, repair, modification, reduction, magnification | H17: servicestores | J17: =CONCATENATE($M$1,$K17) -> DATEERKANTAS.png | K17: ERKANTAS.png | L17: Hizmet Mağazaları | M17: 27.04.2023 | N17: OPENED
A18: ID121A | B18: Vakko L'Atelier | E18: 1 | F18: +905494715909 | G18: çikolata, patisserie, dondurma, bistrot, chocolate, ice cream | H18: restaurant_cafe | I18: www.vakkolatelier.com | J18: =CONCATENATE($M$1,$K18) -> DATEVAKKOLATELIER.png | K18: VAKKOLATELIER.png | L18: Restoran & Cafe | M18: 27.04.2023 | N18: OPENED
A19: ID055 | B19: Gucci | E19: 0 | F19: +902123536533 | H19: fashion | I19: www.gucci.com | J19: =CONCATENATE(Doors!$M$1,$K19) -> https://inmapper.com/zorlucenter/img/logo/GUCCI.png | K19: GUCCI.png | L19: Giyim | M19: 05.05.2023 | N19: OPENED
A20: ID-314 | B20: Design Market | E20: -3 | F20: +902123536847 | G20: takı, tasarım, aksesuar, jewelry, design, accessories | H20: accessories_jewellery | I20: www.designmarket.com.tr | J20: =CONCATENATE($M$1,$K20) -> DATEDESIGNMARKET.png | K20: DESIGNMARKET.png | L20: Aksesuar & Mücevher | M20: 01.06.2023 | N20: CLOSED
A21: ID-137 | B21: Brooks Brothers | E21: -1 | F21: +902123536393 | G21: giyim, kadın, erkek, ayakkabı, moda, clothing, women, men, shoes, fashion, buruks bıradırs | H21: fashion | I21: www.brooksbrothers.com | J21: =CONCATENATE($M$1,$K21) -> DATEBROOKSBROTHERS.png | K21: BROOKSBROTHERS.png | L21: Giyim | M21: 15.06.2023 | N21: CLOSED
A22: ID008 | B22: Saint Laurent | E22: 0 | F22: +902123063390 | G22: erkek, kadın, giyim, moda, ayakkabı, man, woman, clothing, fashion, shoes, sen loren | H22: fashion | I22: www.ysl.com | J22: =CONCATENATE($M$1,$K22) -> DATESAINTLAURENT.png | K22: SAINTLAURENT.png | L22: Giyim | M22: 30.06.2023 | N22: CLOSED
A23: ID008 | B23: Celine | E23: 0 | H23: fashion | L23: Giyim | M23: 30.06.2023 | N23: SOON
A24: ID119F | B24: Boho Loves Elif Mısırlı | E24: 1 | H24: fashion | I24: www.boholoves.com | J24: =CONCATENATE(Doors!$M$1,$K24) -> https://inmapper.com/zorlucenter/img/logo/BOHOLOVESELIFMISIRLI.png | K24: BOHOLOVESELIFMISIRLI.png | L24: Giyim | M24: 11.07.2023 | N24: CLOSED
A25: ID119F | B25: Sagaza | E25: 1 | F25: - | H25: fashion | I25: https://sagaza.com/tr/ | J25: =CONCATENATE(Doors!$M$1,$K25) -> https://inmapper.com/zorlucenter/img/logo/SAGAZA.png | K25: SAGAZA.png | L25: Giyim | M25: 11.07.2023 | N25: OPENED
A26: ID-247 | B26: Tumi | E26: -2 | F26: +902123536676 | H26: shoes_bags | I26: www.tumi.com.tr | J26: =CONCATENATE($M$1,$K26) -> DATETUMI.png | K26: TUMI.png | L26: Ayakkabı & Çanta | M26: 13.07.2023 | N26: OPENED
A27: ID075 | B27: Loro Piana | E27: 0 | F27: +902123536743 | H27: fashion | I27: us.loropiana.com/en | J27: =CONCATENATE($M$1,$K27) -> DATELOROPIANA.png | K27: LOROPIANA.png | L27: Giyim | M27: 27.07.2023 | N27: OPENED
A28: ID-137 | B28: Edwards | E28: -1 | F28: +902123536393 | G28: giyim, kadın, erkek, ayakkabı, moda, clothing, women, men, shoes, fashion, edvırds | H28: fashion | I28: www.edwards.com.tr | J28: =CONCATENATE($M$1,$K28) -> DATEEDWARDS.png | K28: EDWARDS.png | L28: Giyim | M28: 04.08.2023 | N28: OPENED
A29: ID-308 | B29: Watch Doctor | E29: -3 | F29: +902123536949 | G29: saat, pil, kayış, kordon, kadran, watch, battery, strap, cord, dial, voç doktor | H29: servicestores | I29: www.watchdoctor.com.tr | J29: =CONCATENATE(Doors!$M$1,$K29) -> https://inmapper.com/zorlucenter/img/logo/WATCHDOCTOR.png | K29: WATCHDOCTOR.png | L29: Hizmet Mağazaları | M29: 08.08.2023 | N29: CLOSED
A30: ID-118A | B30: Döner Stop | E30: -1 | F30: +902123536622 | G30: fast food, patates, dürüm, sandviç, yemek, fast food, potato roll, sandwich, food, döner sıtop | H30: fastfood | I30: www.donerstop.com.tr | J30: =CONCATENATE(Doors!$M$1,$K30) -> https://inmapper.com/zorlucenter/img/logo/DÖNERSTOP.png | K30: DÖNERSTOP.png | L30: Fast Food | M30: 08.08.2023 | N30: CLOSED
A31: ID066 | B31: Poppin' Bubble Tea & Coffee | E31: 0 | F31: - | G31: Bubble Tea, Coffee, Tea, Mochi, Toppings | H31: restaurant_cafe | I31: www.poppinbubbletea.com | K31: POPPIN.png | L31: Restoran & Cafe | M31: 29.08.2023 | N31: OPENED | O31: N/A 31.12.2023
A32: ID076 | B32: Les Benjamins | E32: 0 | F32: +902123536875 | H32: fashion | I32: www.lesbenjamins.com | J32: =CONCATENATE(Doors!$M$1,$K32) -> https://inmapper.com/zorlucenter/img/logo/LESBENJAMINS.png | K32: LESBENJAMINS.png | L32: Giyim | M32: 09.09.2023 | N32: OPENED
A33: ID-118A | B33: Usta Dönerci | E33: -1 | F33: - | H33: fastfood | I33: www.ustadonerci.com | J33: =CONCATENATE(Doors!$M$1,$K33) -> https://inmapper.com/zorlucenter/img/logo/USTADONERCI.png | K33: USTADONERCI.png | L33: Fast Food | M33: 07.10.2023 | N33: OPENED
A34: ID-308 | B34: Usta Saat | E34: -3 | F34: - | G34: saat, pil, kayış, kordon, kadran, watch, battery, strap, cord, dial, tamir, repair | H34: servicestores | J34: =CONCATENATE(Doors!$M$1,$K34) -> https://inmapper.com/zorlucenter/img/logo/USTASAAT.png | K34: USTASAAT.png | L34: Hizmet Mağazaları | M34: 09.10.2023 | N34: OPENED
A35: ID119F | B35: Sagaza | E35: 1 | F35: - | H35: fashion | I35: www.sagaza.com/tr | J35: =CONCATENATE(Doors!$M$1,$K35) -> https://inmapper.com/zorlucenter/img/logo/SAGAZA.png | K35: SAGAZA.png | L35: Giyim | M35: 05.12.2023 | N35: CLOSED
A36: ID119F | B36: Wabi Sabi | E36: 1 | F36: - | H36: fashion | I36: www.thewabisabi.shop | J36: =CONCATENATE(Doors!$M$1,$K36) -> https://inmapper.com/zorlucenter/img/logo/WABISABI.png | K36: WABISABI.png | L36: Giyim | M36: 15.12.2023 | N36: OPENED | O36: 31.03.2024
A37: ID125 | B37: Yalçınlar | E37: 1 | F37: +902123536700 | G37: fotoğraf, makine, film, baskı, vesikalık, photography, machine, film, printing, mug shot | H37: servicestores | I37: www.fotomaks.com.tr | J37: =CONCATENATE($M$1,$K37) -> DATEYALÇINLAR.png | K37: YALÇINLAR.png | L37: Hizmet Mağazaları | M37: 15.12.2023 | N37: MOVED
A38: ID-316 | B38: Yalçınlar | E38: -3 | F38: +902123536700 | G38: fotoğraf, makine, film, baskı, vesikalık, photography, machine, film, printing, mug shot | H38: servicestores | I38: www.fotomaks.com.tr | J38: =CONCATENATE($M$1,$K38) -> DATEYALÇINLAR.png | K38: YALÇINLAR.png | L38: Hizmet Mağazaları | M38: 15.12.2023 | N38: OPENED
A39: ID-252 | B39: Godiva (Kiosk) | E39: -2 | F39: - | G39: çikolata, tatlı, ülker, hedite, trüf, chocolate, sweet, turkish, gift, truffle | H39: turkishdelight_confectionery | I39: www.godivatr.com | J39: =CONCATENATE($M$1,$K39) -> DATEGODIVA.png | K39: GODIVA.png | L39: Lokum & Şekerleme | M39: 31.12.2023 | N39: CLOSED
A40: ID122 | B40: Riceteria | E40: 1 | F40: +902123536061 | G40: kahve, fincan, hediye, tatlı, coffee, cup, gift, sweet | H40: home_decoration | I40: www.riceteriabyrice.com | J40: =CONCATENATE($M$1,$K40) -> DATERICETERIA.png | K40: RICETERIA.png | L40: Ev & Dekorasyon | M40: 03.01.2024 | N40: CLOSED
...

Sheet Rooms
A1: ID | B1: Title | C1: Subtitle | D1: Location | E1: Floor | F1: Category | G1: Phone | H1: Description
A2: carpark-301 | B2: {“id”:”carpark”} | E2: -3 | F2: other | G2: - | H2: otopark, araç, otomobil, motosiklet, manevra, parking, vehicle, automobile, motorcycle, maneuver
A3: carpark-301 | B3: DRN Oto Yıkama | C3: {“id”:”floorparking”} | E3: -3 | F3: other | G3: +905313051112 | H3: otomobil, yıkama, pasta, cila, temizlik, automobile, washing, cake, lacquer, cleaning
A4: entrance-301 | B4: {“id”:”entrance”} {“id”:”floormetro”} | E4: -3 | F4: other | G4: - | H4: giriş, çıkış, kapı, bekleme, güvenlik, entrance, exit, door, waiting, security
A5: entrance-302 | B5: {“id”:”entrance”} Zincirlikuyu | E5: -3 | F5: other | G5: - | H5: giriş, çıkış, kapı, bekleme, güvenlik, entrance, exit, door, waiting, security
A6: entrance-303 | B6: {“id”:”entrance”} {“id”:”floormetro”} | E6: -3 | F6: other | G6: - | H6: giriş, çıkış, kapı, bekleme, güvenlik, entrance, exit, door, waiting, security
A7: entrance-304 | B7: {“id”:”entrance”} Levazım | E7: -3 | F7: other | G7: - | H7: giriş, çıkış, kapı, bekleme, güvenlik, entrance, exit, door, waiting, security
A8: entrance-305 | B8: {“id”:”entrance”} {“id”:”floorparking”} | E8: -3 | F8: other | G8: - | H8: giriş, çıkış, kapı, bekleme, güvenlik, entrance, exit, door, waiting, security
A9: entrance-306 | B9: {“id”:”entrance”} Eataly | E9: -3 | F9: other | G9: - | H9: giriş, çıkış, kapı, bekleme, güvenlik, entrance, exit, door, waiting, security
A10: ID-301 | B10: Etstur | E10: -3 | F10: other | G10: +902122820808-07 | H10: tatil, deniz, bayram, otel, fırsat, holiday, sea, holidays, hotel, occasion
A11: ID-302 | B11: Levent Lostra | E11: -3 | F11: other | G11: +902123536303 | H11: ayakkabı, tamir, boya, bakım, cüzdan, shoe, repair, paint, maintenance, wallet
A12: ID-303 | B12: Dry Corner | E12: -3 | F12: other | G12: +902123536337 | H12: kuru temizleme, ütü, gömlek, ceket, organik, dry cleaning, ironing, shirt, jacket, organic, dıray kornır
A13: ID-304 | B13: Z Terzi | E13: -3 | F13: other | G13: +902123536986 | H13: dikiş, onarım, tadilat, küçültme, büyültme, sewing, repair, modification, reduction, magnification
A14: ID-306 | B14: Rossmann | E14: -3 | F14: shop | G14: +902123536933 | H14: kozmetik, bakım, temizlik, makyaj, aksesuar, cosmetic, care, cleaning, makeup, accessory, rosman
A15: ID-308 | B15: Watch Doctor | E15: -3 | F15: other | G15: +902123536949 | H15: saat, pil, kayış, kordon, kadran, clock, battery, strap, cord, dial, voç doktor
... A70: ID-245 | B70: Touche | E70: -2 | F70: other | G70: +902129240128 | H70: kulüp, performans, etkinlik, club, performance, event, psm
A71: ID-245 | B71: Zorlu PSM | C71: {“id”:”floormetro”} | E71: -2 | F71: other | G71: +908502226776 | H71: etkinlik, gösteri, tiyatro, konser, bilet, activity, show, theater, concert, ticket
A72: ID-249 | B72: Ametist | E72: -2 | F72: shop | G72: +902123536174 | H72: aksesuar, küpe, kolye, bileklik, yüzük, accessory, earring, necklace, wristband, ring
A73: ID-250 | B73: Lamy | E73: -2 | F73: shop | G73: +902122586715 | H73: lamy, kalem, dolma kalem, tükenmez kalem, versatil kalem, uçlu kalem, roller kalem, alman, lamyshop
A74: ID-251 | B74: Godiva (Kiosk) | E74: -2 | F74: food | G74: - | H74: çikolata, tatlı, ülker, hedite, trüf, chocolate, sweet, turkish, gift, truffle
A75: ID-252 | B75: Dyson | E75: -2 | F75: shop | G75: +905394701299 | H75: süpürge, vakum, toz, vacuum cleaner, vacuum, dust, kablosuz , wireless
A76: ID-253 | B76: Maison Pereja | E76: -2 | F76: shop | G76: - | H76: pereja,kolonya,parfüm,mum,oda parfümü,diffuser, çubuklu oda kokusu, lüks koku
A77: infirmaryEN-201 | B77: {“id”:”infirmary”} | E77: -2 | F77: other | G77: - | H77: eczane, ilaç, reçete, doktor, tedavi, pharmacy, medicine, prescription, doctor, treatment
A78: infirmaryTR-201 | B78: {“id”:”infirmary”} | E78: -2 | F78: other | G78: - | H78: eczane, ilaç, reçete, doktor, tedavi, pharmacy, medicine, prescription, doctor, treatment
A79: info-201 | B79: {“id”:”infodesk”} | E79: -2 | F79: other | G79: +902129240124 | H79: bilgi, danışma, soru, telefon, duyuru, information, consultation, question, phone, announcement
A80: wc-201 | B80: {“id”:”wc”} | E80: -2 | F80: wc | G80: - | H80: tuvalet, lavabo, sabun, mendil, su, toilet, sink, soap, handkerchief, water
A81: wc-202 | B81: {“id”:”wc”} | E81: -2 | F81: wc | G81: - | H81: tuvalet, lavabo, sabun, mendil, su, toilet, sink, soap, handkerchief, water
A82: baby-101 | B82: {“id”:”baby”} | E82: -1 | F82: other | G82: - | H82: bebek, oda, bakım, emzik, meme, baby, room, care, pacifier, breast
A83: baby-102 | B83: {“id”:”baby”} | E83: -1 | F83: other | G83: - | H83: bebek, oda, bakım, emzik, meme, baby, room, care, pacifier, breast
... A108: ID-125 | B108: Et İşleri | E108: -1 | F108: food | G108: - | H108: yemek, ızgara, et, food, grill, meat
A109: ID-126 | B109: Cold Stone Creamery ({"id":"soon"}) | E109: -1 | F109: food | G109: -
A110: ID-127 | B110: Pizza Hut | E110: -1 | F110: food | G110: +908502149034 | H110: yemek, lazanya, fast food, sarımsaklı ekmek, food, lasagna, fast food, garlic bread, pizza hat
A111: ID-128 | B111: Carl's Jr. | E111: -1 | F111: food | G111: +902123536367 | H111: hamburger, patates, fast food, yemek, et, hamburger, potato, fast food, food, meat, karls jünyır
A112: ID-129 | B112: KFC | E112: -1 | F112: food | G112: +905334898893 | H112: tavuk, patates, fast food, yemek, kova, chicken, potato, fast food, food, bucket, keyefsi
A113: ID-130 | B113: Tahin | E113: -1 | F113: food | G113: +902129997078 | H113: yemek, humus, falafel, lübnan, food, humus, falafel, lebanese, ızgara, grill
A114: ID-131 | B114: McDonald's | E114: -1 | F114: food | G114: +905337691842 | H114: hamburger, patates, fast food, yemek, big mac, hamburger, potato, fast food, food, big mac, mekdanılds
A115: ID-133 | B115: Sosa | E115: -1 | F115: food | G115: +902123536280 | H115: yemek, ızgara, salata, makarna, et, food, grilled, salad, pasta, meat
A116: ID-134 | B116: Green Salads | E116: -1 | F116: food | G116: +902123536166 | H116: yemek, ızgara, salata, tavuk, makarna, food, grilled, salad, chicken, pasta, gırin salats
A117: ID-135 | B117: Bobbi Brown | E117: -1 | F117: shop | G117: +902123536449 | H117: kozmetik, makyaj, bakım, kadın, cosmetics, makeup, care, women
A118: ID-135A | B118: Pandora | E118: -1 | F118: shop | G118: +902123536621 | H118: takı, mücevher, pırlanta, yüzük, kolye, jewelry, jewel, diamond, ring, necklace
...

Sheet Portals
A1: ID | B1: Floor | C1: Status
A2: Elev.2.-2 | B2: -3 | C2: On
A3: Elev.3.-2 | B3: -3 | C3: On
A4: Elev.4.-1 | B4: -3 | C4: On
A5: Elev.5.0 | B5: -3 | C5: On
A6: Elev.8.0 | B6: -3 | C6: On
A7: Stairs.10.-2 | B7: -3 | C7: On
A8: Stairs.11.-2 | B8: -3 | C8: On
A9: Stairs.8.0 | B9: -3 | C9: On
A10: Stairs.9.-2 | B10: -3 | C10: On
A11: Elev.2.-1 | B11: -2 | C11: On
A12: Elev.2.-3 | B12: -2 | C12: On
A13: Elev.3.-1 | B13: -2 | C13: On
... A61: Stairs.9.0 | B61: 1 | C61: On

Sheet Info
A1: Angle | B1: 330
A2: W1 | B2: 0
A3: H1 | B3: 0
A4: W2 | B4: 655
A5: H2 | B5: 528
A6: Lat1 | B6: 41.067832
A7: Long1 | B7: 29.018151
A8: Lat2 | B8: 41.065531
A9: Long2 | B9: 29.014361
A10: Wground | B10: =2*6371000*ASIN(SQRT((SIN((B6*(3.14159/180)-B6*(3.14159/180))/2))^2+COS(B6*(3.14159/180))*COS(B6*(3.14159/180))*SIN(((B9*(3.14159/180)-B7*(3.14159/180))/2))^2)) -> 317.72868
A11: Hground | B11: =2*6371000*ASIN(SQRT((SIN((B8*(3.14159/180)-B6*(3.14159/180))/2))^2+COS(B8*(3.14159/180))*COS(B6*(3.14159/180))*SIN(((B7*(3.14159/180)-B7*(3.14159/180))/2))^2)) -> 255.85931
A12: Dground | B12: =2*6371000*ASIN(SQRT((SIN((B8*(3.14159/180)-B6*(3.14159/180))/2))^2+COS(B8*(3.14159/180))*COS(B6*(3.14159/180))*SIN(((B9*(3.14159/180)-B7*(3.14159/180))/2))^2)) -> 407.94489
A13: Dmap | B13: =SQRT((B2-B4)^2+(B3-B5)^2)*0.0002645833 -> 0.2225976
A15: W/H | B15: =B4/B5 -> 1.2405303
A16: Wground/Hground | B16: =B10/B11 -> 1.2418101
A18: var map center | B18: ="["&(B6+B8)/2&", "&(B7+B9)/2&"]" -> [41.0666815, 29.016256]
A19: var bounds | B19: ="["&B6&", "&B7&"]"&", "&"["&B8&", "&B9&"]" -> [41.067832, 29.018151], [41.065531, 29.014361]
A20: var maxBounds | B20: ="["&B6+0.003&", "&B7+0.003&"]"&", "&"["&B8-0.003&", "&B9-0.003&"]" -> [41.070832, 29.021151], [41.062531, 29.011361]
A21: L.inmapperOverlay scale | B21: =B13/B12 -> 0.00054565604

Sheet Kiosk
A1: ID | B1: IP | C1: URL | D1: Konum | E1: Kat | F1: Tip | G1: Yorum | H1: Liste | I1: Kod | J1: Yön | K1: Boyut | M1: Notlar
A2: K-301 | B2: 192.168.187.51 | D2: Güney otopark | F2: Yatay | H2: 1 | I2: wh | J2: Batı (+30 saat yönü) | K2: 692x490 | M2: Kaldırılmış.
A3: K-302 | B3: 192.168.187.52 | C3: =CONCATENATE($N$3,I3,$O$3,A3) -> http://192.168.187.30:8000/eh.html?mode=kiosk&from=K-302 | D3: Balonika önü | E3: P1 Otopark | F3: Yatay | G3: Kalktı mı? | H3: 2 | I3: eh | J3: Doğu (+30 saat yönü) | K3: 692x490 | L3: X-WW | N3: http://192.168.187.30:8000/ | O3: .html?mode=kiosk&from=
A4: K-203 | B4: 192.168.187.53 | C4: =CONCATENATE($N$3,I4,$O$3,A4) -> http://192.168.187.30:8000/sh.html?mode=kiosk&from=K-203 | D4: House of Design yanı, Metro girişi | E4: -2 Metro | F4: Yatay | G4: ripple, RESTART_CHECK | H4: 3 | I4: sh | J4: Güney (+30 saat yönü) | K4: 490x692
A5: K-204 | B5: 192.168.187.54 | C5: =CONCATENATE($N$3,I5,$O$3,A5) -> http://192.168.187.30:8000/sh.html?mode=kiosk&from=K-204 | D5: Tartine et Chocolat önü | F5: Yatay | H5: 4 | I5: sh | J5: Güney (+30 saat yönü) | K5: 490x692 | M5: Kaldırılmış.
A6: K-207 | B6: 192.168.187.55 | C6: =CONCATENATE($N$3,I6,$O$3,A6) -> http://192.168.187.30:8000/nh.html?mode=kiosk&from=K-207 | D6: H&M önü, Penti tarafı | E6: -2 Metro | F6: Yatay | G6: msedge, RESTART_CHECK | I6: nh | J6: Kuzey (+30 saat yönü) | K6: 490x692 | L6: W | M6: Dokunmatiği çalışmıyor.
A7: K-206 | B7: 192.168.187.56 | C7: =CONCATENATE($N$3,I7,$O$3,A7) -> http://192.168.187.30:8000/sh.html?mode=kiosk&from=K-206 | D7: H&M önü, Perspective tarafı | E7: -2 Metro | F7: Yatay | G7: RESTART, ripple | H7: 6 | I7: sh | J7: Güney (+30 saat yönü) | K7: 490x692 | L7: X
A8: K-110 | B8: 192.168.187.100 | C8: =CONCATENATE($N$3,I8,$O$3,A8) -> http://192.168.187.30:8000/nh.html?mode=kiosk&from=K-110 | D8: Apple (Boğaz) önü, Zen Pırlanta tarafı | E8: -1 Boğaz | F8: Yatay | G8: RESTART, ripple | I8: nh | J8: Kuzey (+30 saat yönü) | K8: 490x692 | L8: W
A9: K-108 | B9: 192.168.187.58 | C9: =CONCATENATE($N$3,I9,$O$3,A9) -> http://192.168.187.30:8000/sh.html?mode=kiosk&from=K-108 | D9: Apple (Boğaz) önü, Lacoste tarafı | E9: -1 Boğaz | F9: Yatay | G9: radmin | H9: 8 | I9: sh | J9: Güney (+30 saat yönü) | K9: 490x692 | L9: W | M9: Görsel geçişi sorunlu. / Formatlandı.
A10: K-109 | B10: 192.168.187.59 | C10: =CONCATENATE($N$3,I10,$O$3,A10) -> http://192.168.187.30:8000/wh.html?mode=kiosk&from=K-109 | D10: Levazım girişi, Brooks Brothers karşısı | E10: -1 Boğaz | F10: Yatay | G10: radmin | H10: 9 | I10: wh | J10: Batı (+30 saat yönü) | K10: 692x490 | L10: W | M10: Görsel geçişi sorunlu. / Formatlandı.
A11: K021 | B11: 192.168.187.60 | C11: =CONCATENATE($N$3,I11,$O$3,A11) -> http://192.168.187.30:8000/sv.html?mode=kiosk&from=K021 | D11: Meydan katı Metro çıkışı, Sail Loft Vakkorama önde kalacak | E11: 0 Meydan | F11: Dikey | G11: - | H11: 21 | I11: sv | J11: Güney (+30 saat yönü) | K11: 490x692 | L11: X | M11: Görsel geçişi sorunlu. / Dokunmatiği çalışmıyor.
A12: K022 | B12: 192.168.187.61 | C12: =CONCATENATE($N$3,I12,$O$3,A12) -> http://192.168.187.30:8000/sv.html?mode=kiosk&from=K022 | D12: Vakko önü, Vakko sağda kalacak | E12: 0 Meydan | F12: Dikey | G12: RADMIN, CONN_CHECK | H12: 22 | I12: sv | J12: Güney (+30 saat yönü) | K12: 490x692 | M12: Dokunmatiği çalışmıyor.
A13: K012 | B13: 192.168.187.62 | C13: =CONCATENATE($N$3,I13,$O$3,A13) -> http://192.168.187.30:8000/nh.html?mode=kiosk&from=K012 | D13: Godiva yanı, asansör önü | E13: 0 Meydan | F13: Yatay | G13: RESTART, ripple | H13: 12 | I13: nh | J13: Kuzey (+30 saat yönü) | K13: 490x692 | L13: W | M13: Görsel geçişi sorunlu. / Formatlandı.
A14: K014 | B14: 192.168.187.64 | C14: =CONCATENATE($N$3,I14,$O$3,A14) -> http://192.168.187.30:8000/nv.html?mode=kiosk&from=K014 | D14: Parle önü, Apple camı arkada kalacak | F14: Dikey | H14: 14 | I14: nv | J14: Kuzey (+30 saat yönü) | K14: 490x692 | M14: Kaldırılmış.
A15: K025 | B15: 192.168.187.65 | C15: =CONCATENATE($N$3,I15,$O$3,A15) -> http://192.168.187.30:8000/sv.html?mode=kiosk&from=K025 | D15: Dolce&Gabbana önü, Dolce&Gabbana sağda kalacak | E15: 0 Meydan | F15: Dikey | G15: - | H15: 25 | I15: sv | J15: Güney (+30 saat yönü) | K15: 490x692 | M15: Dokunmatiği çalışmıyor.
A16: K016 | B16: 192.168.187.66 | C16: =CONCATENATE($N$3,I16,$O$3,A16) -> http://192.168.187.30:8000/nh.html?mode=kiosk&from=K016 | D16: Saray Muhallebicisi önü | E16: 0 Meydan | F16: Yatay | G16: ripple | H16: 16 | I16: nh | J16: Kuzey (+30 saat yönü) | K16: 490x692 | L16: W | M16: Formatlandı. / Kapatıldı.
A17: K118 | B17: 192.168.187.68 | C17: =CONCATENATE($N$3,I17,$O$3,A17) -> http://192.168.187.30:8000/wh.html?mode=kiosk&from=K118 | D17: Miele önü, merdiven çıkışı | E17: 1 Köprü | F17: Yatay | G17: ripple | H17: 18 | I17: wh | J17: Batı (+30 saat yönü) | K17: 692x490 | L17: W | M17: Görsel geçişi sorunlu. / Formatlandı.
A18: K119 | B18: 192.168.187.69 | C18: =CONCATENATE($N$3,I18,$O$3,A18) -> http://192.168.187.30:8000/nv.html?mode=kiosk&from=K119 | D18: Zanzibar önü, Zanzibar önde kalacak | F18: Dikey | H18: 19 | I18: nv | J18: Kuzey (+30 saat yönü) | K18: 490x692 | M18: Kaldırılmış.
A19: K024 | B19: 192.168.187.74 | C19: =CONCATENATE($N$3,I19,$O$3,A19) -> http://192.168.187.30:8000/sv.html?mode=kiosk&from=K024 | D19: Parle önü, Apple camı önde kalacak | F19: Dikey | H19: 24 | I19: sv | J19: Güney (+30 saat yönü) | K19: 490x692 | M19: Kaldırılmış.
A20: K120 | B20: 192.168.187.70 | C20: =CONCATENATE($N$3,I20,$O$3,A20) -> http://192.168.187.30:8000/sh.html?mode=kiosk&from=K120 | D20: Funloft yanı | E20: 1 Köprü | F20: Yatay | G20: radmin | H20: 20 | I20: sh | J20: Güney (+30 saat yönü) | K20: 490x692 | L20: W | M20: Yeniden başlamış gibi. / Formatlandı.
A21: K010 | B21: 192.168.187.71 | C21: =CONCATENATE($N$3,I21,$O$3,A21) -> http://192.168.187.30:8000/nv.html?mode=kiosk&from=K010 | D21: Meydan katı Metro çıkışı, Sail Loft Vakkorama arkada kalacak | E21: 0 Meydan | F21: Dikey | G21: CONN_CHECK | H21: 10 | I21: nv | J21: Kuzey (+30 saat yönü) | K21: 490x692 | M21: Dokunmatik sorunu var, Vestel bakacak. / Düzeldi.
A22: K011 | B22: 192.168.187.72 | C22: =CONCATENATE($N$3,I22,$O$3,A22) -> http://192.168.187.30:8000/nv.html?mode=kiosk&from=K011 | D22: Vakko önü, Vakko solda kalacak | E22: 0 Meydan | F22: Dikey | G22: - | H22: 11 | I22: nv | J22: Kuzey (+30 saat yönü) | K22: 490x692 | M22: Görsel geçişi sorunlu.
A23: K015 | B23: 192.168.187.75 | C23: =CONCATENATE($N$3,I23,$O$3,A23) -> http://192.168.187.30:8000/nv.html?mode=kiosk&from=K015 | D23: Dolce&Gabbana önü, Dolce&Gabbana solda kalacak | E23: 0 Meydan | F23: Dikey | G23: - | H23: 15 | I23: nv | J23: Kuzey (+30 saat yönü) | K23: 490x692 | M23: Formatlandı.
A24: K023 | B24: 192.168.187.77 | C24: =CONCATENATE($N$3,I24,$O$3,A24) -> http://192.168.187.30:8000/wh.html?mode=kiosk&from=K023 | D24: Ulus girişi | E24: 0 Meydan | F24: Yatay | G24: Kalktı mı? | I24: wh | J24: Doğu (+30 saat yönü) | K24: 692x490 | L24: W
A25: K127 | B25: 192.168.187.77 | D25: Zanzibar önü, Zanzibar arkada kalacak | F25: Dikey | H25: 27 | I25: sv | J25: Güney (+30 saat yönü) | K25: 490x692 | M25: Kaldırılmış.
A26: TST | B26: 192.168.187.46 | M26: 65"
A27: TST | B27: 192.168.187.47
A28: K-205 | B28: 192.168.187.55 | D28: Apple (Metro) önü | F28: Yatay | H28: 5 | I28: sh | J28: Güney (+30 saat yönü) | K28: 490x692 | M28: Formatlandı. / 14.05.2020'ye kadar kalktı
A29: K-107 | B29: 192.168.187.57 | D29: Zip Car önü | F29: Yatay | H29: 7 | I29: sh | J29: Güney (+30 saat yönü) | K29: 490x692 | M29: Formatlandı.
A30: K023 | B30: 192.168.187.73 | D30: Five O'Clock önü, Sokak önde kalacak | F30: Dikey | H30: 23 | I30: ev | J30: Batı (+30 saat yönü) | K30: 692x490
A31: K013 | B31: 192.168.187.63 | D31: Five O'Clock önü, Sokak arkada kalacak | F31: Dikey | H31: 13 | I31: wv | J31: Doğu (+30 saat yönü) | K31: 692x490
A32: K026 | B32: 192.168.187.76 | D32: Tiffany önü, Sokak arkada kalacak | F32: Dikey | H32: 26 | I32: nv | J32: Kuzey (+30 saat yönü) | K32: 490x692
A33: K017 | B33: 192.168.187.67 | D33: Tiffany önü, Sokak önde kalacak | F33: Dikey | H33: 17 | I33: sv | J33: Güney (+30 saat yönü) | K33: 490x692

Sheet QR
A1: ID | B1: QR | C1: Floor | D1: Link | E1: Location
